
Похожий случай, используем то же самое .sideeffect у объекта класса Mock (примерно так, я не использовал UnitTest, не знаю, работает ли код) если кто-то умнее, можете попробовать разобраться в ответе [sof](https://stackoverflow.com/questions/74563124/raise-an-exception-using-mock-when-a-specific-django-model-is-called/74563586#74563586)

```python

@patch.object(ObjectClass, 'name_of_method')
def test_object1(self, mock_method):
	mock_method.side_effect = Exception(ValueError)

```
